<!DOCTYPE html>
<html lang="en">
<head>
 <meta charset="UTF-8">
 <title>Title</title>
</head>
<body>
<script>
 const promise = new Promise(function (resolve, reject) {
  resolve('ok');
  setTimeout(function () { throw new Error('test') }, 0) ;
  // Promise 指定在下一轮“事件循环”再抛出错误。
  // 到了那个时候，Promise 的运行已经结束了，所以这个错误是在 Promise 函数体外抛出的，会冒泡到最外层，成了未捕获的错误
 });
 promise.then(function (value) { console.log(value) });
 setTimeout(() => { console.log(123) }, 2000);


/* ok
 Uncaught Error: test at promise2-3catch.html:11
 123*/



//  浏览器运行到 resolve(x + 2);，会打印出错误提示ReferenceError: x is not defined，但是不会退出进程、终止脚本执行
//  2 秒之后还是会输出123。这就是说，Promise 内部的错误不会影响到 Promise 外部的代码，通俗的说法就是“Promise 会吃掉错误”。
/* const someAsyncThing = function() {
  return new Promise(function(resolve, reject) {
   // 下面一行会报错，因为x没有声明
   resolve(x + 2);
  });
 };

 someAsyncThing().then(function() {
  console.log('everything is great');
 });

 setTimeout(() => { console.log(123) }, 2000);*/

/*
上面代码输出结果：
Uncaught (in promise) ReferenceError: x is not defined
 123
 */

</script>
</body>
</html>